<?xml version="1.0" encoding="utf-8"?>
<!--
This URDF was automatically created by SolidWorks to URDF Exporter! Originally created by Stephen Brawner (brawner@gmail.com)
Commit Version: 1.6.0-4-g7f85cfe  Build Version: 1.6.7995.38578
For more information, please see http://wiki.ros.org/sw_urdf_exporter
-->
<robot name="pai_2_12_240723">
	<link name="base_link">
		<inertial>
			<origin xyz="0.02264846 -0.00004298 0.03856462" rpy="0 0 0" />
			<mass value="1.767987723282303" />
			<inertia ixx="0.00715641" ixy="-0.00000351" ixz="-0.00040457" iyy="0.00754610" iyz="0.00000400" izz="0.00985603" />
		</inertial>
		<visual>
			<origin xyz="0 0 0" rpy="0 0 0" />
			<geometry>
				<mesh filename="package://pai_2_12_240723/meshes/base_link.STL" />
			</geometry>
			<material name="">
				<color rgba="0.752941176470588 0.752941176470588 0.752941176470588 1" />
			</material>
		</visual>
		<collision>
			<origin xyz="0 0 0" rpy="0 0 0" />
			<geometry>
				<mesh filename="package://pai_2_12_240723/meshes/base_link.STL" />
			</geometry>
		</collision>
	</link>
	<link name="r_hip_yaw_link">
		<inertial>
			<origin xyz="-0.05317432 -0.00007017 -0.05024259" rpy="0 0 0" />
			<mass value="0.40825297" />
			<inertia ixx="0.00024215" ixy="-0.00000027" ixz="-0.00006446" iyy="0.00026252" iyz="0.00000037" izz="0.00016997" />
		</inertial>
		<visual>
			<origin xyz="0 0 0" rpy="0 0 0" />
			<geometry>
				<mesh filename="package://pai_2_12_240723/meshes/r_hip_yaw_link.STL" />
			</geometry>
			<material name="">
				<color rgba="0.75294 0.75294 0.75294 1" />
			</material>
		</visual>
		<collision>
			<origin xyz="0 0 0" rpy="0 0 0" />
			<geometry>
				<mesh filename="package://pai_2_12_240723/meshes/r_hip_yaw_link.STL" />
			</geometry>
		</collision>
	</link>
	<joint name="r_hip_yaw_joint" type="revolute">
		<origin xyz="-0.003125 -0.075 -0.009" rpy="0 0 0" />
		<parent link="base_link" />
		<child link="r_hip_yaw_link" />
		<axis xyz="0 0 1" />
		<limit lower="-0.6" upper="0.6" effort="21" velocity="21" />
	</joint>
	<link name="r_hip_roll_link">
		<inertial>
			<origin xyz="-0.00165182 0.0 0.00009013" rpy="0 0 0" />
			<mass value="0.75405217" />
			<inertia ixx="0.00114977" ixy="0.0" ixz="0.00000182" iyy="0.00031770" iyz="0.00000238" izz="0.00117774" />
		</inertial>
		<visual>
			<origin xyz="0 0 0" rpy="0 0 0" />
			<geometry>
				<mesh filename="package://pai_2_12_240723/meshes/r_hip_roll_link.STL" />
			</geometry>
			<material name="">
				<color rgba="0.752941176470588 0.752941176470588 0.752941176470588 1" />
			</material>
		</visual>
		<collision>
			<origin xyz="0 0 0" rpy="0 0 0" />
			<geometry>
				<mesh filename="package://pai_2_12_240723/meshes/r_hip_roll_link.STL" />
			</geometry>
		</collision>
	</link>
	<joint name="r_hip_roll_joint" type="revolute">
		<origin xyz="0 0 -0.056" rpy="0 0 0" />
		<parent link="r_hip_yaw_link" />
		<child link="r_hip_roll_link" />
		<axis xyz="1 0 0" />
		<limit lower="-0.4" upper="0.22" effort="21" velocity="21" />
	</joint>
	<link name="r_thigh_link">
		<inertial>
			<origin xyz="0.00012218 -0.00135823 -0.06908333" rpy="0 0 0" />
			<mass value="0.21894101" />
			<inertia ixx="0.00076454" ixy="0.00000004" ixz="0.00000008" iyy="0.00077056" iyz="0.00002142" izz="0.00004054" />
		</inertial>
		<visual>
			<origin xyz="0 0 0" rpy="0 0 0" />
			<geometry>
				<mesh filename="package://pai_2_12_240723/meshes/r_thigh_link.STL" />
			</geometry>
			<material name="">
				<color rgba="0.752941176470588 0.752941176470588 0.752941176470588 1" />
			</material>
		</visual>
		<collision>
			<origin xyz="0 0 0" rpy="0 0 0" />
			<geometry>
				<mesh filename="package://pai_2_12_240723/meshes/r_thigh_link.STL" />
			</geometry>
		</collision>
	</link>
	<joint name="r_thigh_joint" type="revolute">
		<origin xyz="0 0 0" rpy="0 0.05009 0" />
		<parent link="r_hip_roll_link" />
		<child link="r_thigh_link" />
		<axis xyz="0 1 0" />
		<limit lower="-2.25" upper="0.4" effort="21" velocity="21" />
	</joint>
	<link name="r_calf_link">
		<inertial>
			<origin xyz="-0.00242534 0.00004312 -0.09732545" rpy="0 0 0" />
			<mass value="0.94531081" />
			<inertia ixx="0.00125228" ixy="0.00000083" ixz="-0.00009452" iyy="0.00124644" iyz="-0.00006385" izz="0.00023470" />
		</inertial>
		<visual>
			<origin xyz="0 0 0" rpy="0 0 0" />
			<geometry>
				<mesh filename="package://pai_2_12_240723/meshes/r_calf_link.STL" />
			</geometry>
			<material name="">
				<color rgba="0.752941176470588 0.752941176470588 0.752941176470588 1" />
			</material>
		</visual>
		<collision>
			<origin xyz="0 0 0" rpy="0 0 0" />
			<geometry>
				<mesh filename="package://pai_2_12_240723/meshes/r_calf_link.STL" />
			</geometry>
		</collision>
	</link>
	<joint name="r_calf_joint" type="revolute">
		<origin xyz="0.0075 0 -0.149812382665786" rpy="0 -0.05009 0" />
		<parent link="r_thigh_link" />
		<child link="r_calf_link" />
		<axis xyz="0 1 0" />
		<limit lower="0.0" upper="2.37" effort="21" velocity="21" />
	</joint>
	<link name="r_ankle_pitch_link">
		<inertial>
			<origin xyz="-1.6509E-07 -3.5454E-07 1.0424E-08" rpy="0 0 0" />
			<mass value="0.01180204" />
			<inertia ixx="0.00000047" ixy="8.2515E-14" ixz="-8.8688E-13" iyy="0.00000111" iyz="1.3362E-12" izz="0.00000121" />
		</inertial>
		<visual>
			<origin xyz="0 0 0" rpy="0 0 0" />
			<geometry>
				<mesh filename="package://pai_2_12_240723/meshes/r_ankle_pitch_link.STL" />
			</geometry>
			<material name="">
				<color rgba="0.89804 0.91765 0.92941 1" />
			</material>
		</visual>
		<collision>
			<origin xyz="0 0 0" rpy="0 0 0" />
			<geometry>
				<mesh filename="package://pai_2_12_240723/meshes/r_ankle_pitch_link.STL" />
			</geometry>
		</collision>
	</link>
	<joint name="r_ankle_pitch_joint" type="revolute">
		<origin xyz="0 0 -0.17495" rpy="0 0 0" />
		<parent link="r_calf_link" />
		<child link="r_ankle_pitch_link" />
		<axis xyz="0 1 0" />
		<limit lower="-0.83" upper="0.59" effort="21" velocity="21" />
	</joint>
	<link name="r_ankle_roll_link">
		<inertial>
			<origin xyz="0.01979902 0.00000141 -0.02023932" rpy="0 0 0" />
			<mass value="0.18592619" />
			<inertia ixx="0.00006786" ixy="0.00000000" ixz="0.00001824" iyy="0.00024654" iyz="0.00000000" izz="0.00028950" />
		</inertial>
		<visual>
			<origin xyz="0 0 0" rpy="0 0 0" />
			<geometry>
				<mesh filename="package://pai_2_12_240723/meshes/r_ankle_roll_link.STL" />
			</geometry>
			<material name="">
				<color rgba="0.752941176470588 0.752941176470588 0.752941176470588 1" />
			</material>
		</visual>
		<collision>
			<origin xyz="0 0 0" rpy="0 0 0" />
			<geometry>
				<mesh filename="package://pai_2_12_240723/meshes/r_ankle_roll_link.STL" />
			</geometry>
		</collision>
	</link>
	<joint name="r_ankle_roll_joint" type="revolute">
		<origin xyz="0 0 0" rpy="0 0 0" />
		<parent link="r_ankle_pitch_link" />
		<child link="r_ankle_roll_link" />
		<axis xyz="1 0 0" />
		<limit lower="-0.4" upper="0.4" effort="21" velocity="21" />
	</joint>
	<link name="l_hip_yaw_link">
		<inertial>
			<origin xyz="-0.05317432 -0.00007017 -0.05024259" rpy="0 0 0" />
			<mass value="0.40825297" />
			<inertia ixx="0.00024215" ixy="-0.00000027" ixz="-0.00006446" iyy="0.00026252" iyz="0.00000037" izz="0.00016997" />
		</inertial>
		<visual>
			<origin xyz="0 0 0" rpy="0 0 0" />
			<geometry>
				<mesh filename="package://pai_2_12_240723/meshes/l_hip_yaw_link.STL" />
			</geometry>
			<material name="">
				<color rgba="0.75294 0.75294 0.75294 1" />
			</material>
		</visual>
		<collision>
			<origin xyz="0 0 0" rpy="0 0 0" />
			<geometry>
				<mesh filename="package://pai_2_12_240723/meshes/l_hip_yaw_link.STL" />
			</geometry>
		</collision>
	</link>
	<joint name="l_hip_yaw_joint" type="revolute">
		<origin xyz="-0.003125 0.075 -0.009" rpy="0 0 0" />
		<parent link="base_link" />
		<child link="l_hip_yaw_link" />
		<axis xyz="0 0 1" />
		<limit lower="-0.6" upper="0.6" effort="21" velocity="21" />
	</joint>
	<link name="l_hip_roll_link">
		<inertial>
			<origin xyz="-0.00165182 0.0 0.00009013" rpy="0 0 0" />
			<mass value="0.75405217" />
			<inertia ixx="0.00114977" ixy="0.0" ixz="0.00000182" iyy="0.00031770" iyz="0.00000238" izz="0.00117774" />
		</inertial>
		<visual>
			<origin xyz="0 0 0" rpy="0 0 0" />
			<geometry>
				<mesh filename="package://pai_2_12_240723/meshes/l_hip_roll_link.STL" />
			</geometry>
			<material name="">
				<color rgba="0.752941176470588 0.752941176470588 0.752941176470588 1" />
			</material>
		</visual>
		<collision>
			<origin xyz="0 0 0" rpy="0 0 0" />
			<geometry>
				<mesh filename="package://pai_2_12_240723/meshes/l_hip_roll_link.STL" />
			</geometry>
		</collision>
	</link>
	<joint name="l_hip_roll_joint" type="revolute">
		<origin xyz="0 0 -0.056" rpy="0 0 0" />
		<parent link="l_hip_yaw_link" />
		<child link="l_hip_roll_link" />
		<axis xyz="1 0 0" />
		<limit lower="-0.22" upper="0.4" effort="21" velocity="21" />
	</joint>
	<link name="l_thigh_link">
		<inertial>
			<origin xyz="0.00012218 -0.00135823 -0.06908333" rpy="0 0 0" />
			<mass value="0.21894101" />
			<inertia ixx="0.00076454" ixy="0.00000004" ixz="0.00000008" iyy="0.00077056" iyz="0.00002142" izz="0.00004054" />
		</inertial>
		<visual>
			<origin xyz="0 0 0" rpy="0 0 0" />
			<geometry>
				<mesh filename="package://pai_2_12_240723/meshes/l_thigh_link.STL" />
			</geometry>
			<material name="">
				<color rgba="0.752941176470588 0.752941176470588 0.752941176470588 1" />
			</material>
		</visual>
		<collision>
			<origin xyz="0 0 0" rpy="0 0 0" />
			<geometry>
				<mesh filename="package://pai_2_12_240723/meshes/l_thigh_link.STL" />
			</geometry>
		</collision>
	</link>
	<joint name="l_thigh_joint" type="revolute">
		<origin xyz="0 0 0" rpy="0 0 0" />
		<parent link="l_hip_roll_link" />
		<child link="l_thigh_link" />
		<axis xyz="0 1 0" />
		<limit lower="-2.25" upper="0.4" effort="21" velocity="21" />
	</joint>
	<link name="l_calf_link">
		<inertial>
			<origin xyz="-0.00242534 0.00004312 -0.09732545" rpy="0 0 0" />
			<mass value="0.94531081" />
			<inertia ixx="0.00125228" ixy="0.00000083" ixz="-0.00009452" iyy="0.00124644" iyz="-0.00006385" izz="0.00023470" />
		</inertial>
		<visual>
			<origin xyz="0 0 0" rpy="0 0 0" />
			<geometry>
				<mesh filename="package://pai_2_12_240723/meshes/l_calf_link.STL" />
			</geometry>
			<material name="">
				<color rgba="0.75294 0.75294 0.75294 1" />
			</material>
		</visual>
		<collision>
			<origin xyz="0 0 0" rpy="0 0 0" />
			<geometry>
				<mesh filename="package://pai_2_12_240723/meshes/l_calf_link.STL" />
			</geometry>
		</collision>
	</link>
	<joint name="l_calf_joint" type="revolute">
		<origin xyz="0.0075 0 -0.149812382665786" rpy="0 0 0" />
		<parent link="l_thigh_link" />
		<child link="l_calf_link" />
		<axis xyz="0 1 0" />
		<limit lower="0.0" upper="2.37" effort="21" velocity="21" />
	</joint>
	<link name="l_ankle_pitch_link">
		<inertial>
			<origin xyz="-1.6509E-07 -3.5454E-07 1.0424E-08" rpy="0 0 0" />
			<mass value="0.01180204" />
			<inertia ixx="0.00000047" ixy="8.2515E-14" ixz="-8.8688E-13" iyy="0.00000111" iyz="1.3362E-12" izz="0.00000121" />
		</inertial>
		<visual>
			<origin xyz="0 0 0" rpy="0 0 0" />
			<geometry>
				<mesh filename="package://pai_2_12_240723/meshes/l_ankle_pitch_link.STL" />
			</geometry>
			<material name="">
				<color rgba="0.898039215686275 0.917647058823529 0.929411764705882 1" />
			</material>
		</visual>
		<collision>
			<origin xyz="0 0 0" rpy="0 0 0" />
			<geometry>
				<mesh filename="package://pai_2_12_240723/meshes/l_ankle_pitch_link.STL" />
			</geometry>
		</collision>
	</link>
	<joint name="l_ankle_pitch_joint" type="revolute">
		<origin xyz="0 0 -0.17495" rpy="0 0 0" />
		<parent link="l_calf_link" />
		<child link="l_ankle_pitch_link" />
		<axis xyz="0 1 0" />
		<limit lower="-0.83" upper="0.59" effort="21" velocity="21" />
	</joint>
	<link name="l_ankle_roll_link">
		<inertial>
			<origin xyz="0.01979902 0.00000141 -0.02023932" rpy="0 0 0" />
			<mass value="0.18592619" />
			<inertia ixx="0.00006786" ixy="0.00000000" ixz="0.00001824" iyy="0.00024654" iyz="0.00000000" izz="0.00028950" />
		</inertial>
		<visual>
			<origin xyz="0 0 0" rpy="0 0 0" />
			<geometry>
				<mesh filename="package://pai_2_12_240723/meshes/l_ankle_roll_link.STL" />
			</geometry>
			<material name="">
				<color rgba="0.752941176470588 0.752941176470588 0.752941176470588 1" />
			</material>
		</visual>
		<collision>
			<origin xyz="0 0 0" rpy="0 0 0" />
			<geometry>
				<mesh filename="package://pai_2_12_240723/meshes/l_ankle_roll_link.STL" />
			</geometry>
		</collision>
	</link>
	<joint name="l_ankle_roll_joint" type="revolute">
		<origin xyz="0 0 0" rpy="0 0 0" />
		<parent link="l_ankle_pitch_link" />
		<child link="l_ankle_roll_link" />
		<axis xyz="1 0 0" />
		<limit lower="-0.4" upper="0.4" effort="21" velocity="21" />
	</joint>
</robot>
