<?xml version="1.0" encoding="utf-8"?>
<!--
This URDF was automatically created by SolidWorks to URDF Exporter! Originally created by Stephen Brawner (brawner@gmail.com)
Commit Version: 1.6.0-4-g7f85cfe  Build Version: 1.6.7995.38578
For more information, please see http://wiki.ros.org/sw_urdf_exporter
-->
<robot name="pai_cl_12_240823">
	<link name="base_link">
		<inertial>
			<origin xyz="0.0019787 -0.00010049 0.05148923" rpy="0 0 0" />
			<mass value="1.28649761" />
			<inertia ixx="0.00561051" ixy="-1.201E-05" ixz="-3.402E-05" iyy="0.00672272" iyz="8.27E-06" izz="0.003739" />
		</inertial>
		<visual>
			<origin xyz="0 0 0" rpy="0 0 0" />
			<geometry>
				<mesh filename="package://pai_cl_12_240823/meshes/base_link.STL" />
			</geometry>
			<material name="">
				<color rgba="0.79216 0.81961 0.93333 1" />
			</material>
		</visual>
		<collision>
			<origin xyz="0 0 0" rpy="0 0 0" />
			<geometry>
				<mesh filename="package://pai_cl_12_240823/meshes/base_link.STL" />
			</geometry>
		</collision>
	</link>
	<link name="r_hip_yaw_link">
		<inertial>
			<origin xyz="0.00173618 -0.0312122 -0.00030829" rpy="0 0 0" />
			<mass value="0.34618014" />
			<inertia ixx="0.00017286" ixy="-3.5E-07" ixz="-7.7E-07" iyy="0.00016647" iyz="1.75E-06" izz="0.00017435" />
		</inertial>
		<visual>
			<origin xyz="0 0 0" rpy="0 0 0" />
			<geometry>
				<mesh filename="package://pai_cl_12_240823/meshes/r_hip_yaw_link.STL" />
			</geometry>
			<material name="">
				<color rgba="0.79216 0.81961 0.93333 1" />
			</material>
		</visual>
		<collision>
			<origin xyz="0 0 0" rpy="0 0 0" />
			<geometry>
				<mesh filename="package://pai_cl_12_240823/meshes/r_hip_yaw_link.STL" />
			</geometry>
		</collision>
	</link>
	<joint name="r_hip_yaw_joint" type="revolute">
		<origin xyz="-0.0028186 -0.0482 -0.031" rpy="0 0 0" />
		<parent link="base_link" />
		<child link="r_hip_yaw_link" />
		<axis xyz="0 1 0" />
		<limit lower="-3.14" upper="3.14" effort="21" velocity="21" />
	</joint>
	<link name="r_hip_roll_link">
		<inertial>
			<origin xyz="-0.025898 0.00026595 -0.061275" rpy="0 0 0" />
			<mass value="0.3854" />
			<inertia ixx="0.00036232" ixy="1.64E-06" ixz="3.175E-05" iyy="0.00042107" iyz="2.7E-07" izz="0.00022943" />
		</inertial>
		<visual>
			<origin xyz="0 0 0" rpy="0 0 0" />
			<geometry>
				<mesh filename="package://pai_cl_12_240823/meshes/r_hip_roll_link.STL" />
			</geometry>
			<material name="">
				<color rgba="0.79216 0.81961 0.93333 1" />
			</material>
		</visual>
		<collision>
			<origin xyz="0 0 0" rpy="0 0 0" />
			<geometry>
				<mesh filename="package://pai_cl_12_240823/meshes/r_hip_roll_link.STL" />
			</geometry>
		</collision>
	</link>
	<joint name="r_hip_roll_joint" type="revolute">
		<origin xyz="0.0245 -0.032 0" rpy="0 0 0" />
		<parent link="r_hip_yaw_link" />
		<child link="r_hip_roll_link" />
		<axis xyz="1 0 0" />
		<limit lower="-3.14" upper="3.14" effort="21" velocity="21" />
	</joint>
	<link name="r_thigh_link">
		<inertial>
			<origin xyz="0 0.01330199 -0.03045083" rpy="0 0 0" />
			<mass value="0.07450262" />
			<inertia ixx="7.117E-05" ixy="0" ixz="0" iyy="3.643E-05" iyz="8.15E-06" izz="5.176E-05" />
		</inertial>
		<visual>
			<origin xyz="0 0 0" rpy="0 0 0" />
			<geometry>
				<mesh filename="package://pai_cl_12_240823/meshes/r_thigh_link.STL" />
			</geometry>
			<material name="">
				<color rgba="0.79216 0.81961 0.93333 1" />
			</material>
		</visual>
		<collision>
			<origin xyz="0 0 0" rpy="0 0 0" />
			<geometry>
				<mesh filename="package://pai_cl_12_240823/meshes/r_thigh_link.STL" />
			</geometry>
		</collision>
	</link>
	<joint name="r_thigh_joint" type="revolute">
		<origin xyz="-0.0245 0 -0.0935" rpy="0 0 0" />
		<parent link="r_hip_roll_link" />
		<child link="r_thigh_link" />
		<axis xyz="0 0 1" />
		<limit lower="-3.14" upper="3.14" effort="21" velocity="21" />
	</joint>
	<link name="r_calf_link">
		<inertial>
			<origin xyz="4.901E-05 0.023851 -0.070145" rpy="0 0 0" />
			<mass value="0.7282" />
			<inertia ixx="0.0032286" ixy="7E-08" ixz="-8.9E-06" iyy="0.003247" iyz="1.946E-05" izz="0.0003019" />
		</inertial>
		<visual>
			<origin xyz="0 0 0" rpy="0 0 0" />
			<geometry>
				<mesh filename="package://pai_cl_12_240823/meshes/r_calf_link.STL" />
			</geometry>
			<material name="">
				<color rgba="0.75294 0.75294 0.75294 1" />
			</material>
		</visual>
		<collision>
			<origin xyz="0 0 0" rpy="0 0 0" />
			<geometry>
				<mesh filename="package://pai_cl_12_240823/meshes/r_calf_link.STL" />
			</geometry>
		</collision>
	</link>
	<joint name="r_calf_joint" type="revolute">
		<origin xyz="0 -0.0275 -0.046" rpy="0 0 0" />
		<parent link="r_thigh_link" />
		<child link="r_calf_link" />
		<axis xyz="0 1 0" />
		<limit lower="-3.14" upper="3.14" effort="21" velocity="21" />
	</joint>
	<link name="r_ankle_pitch_link">
		<inertial>
			<origin xyz="0.025777 0.028546 0" rpy="0 0 0" />
			<mass value="0.13223" />
			<inertia ixx="9.848E-05" ixy="3.56E-06" ixz="0" iyy="7.022E-05" iyz="0" izz="0.00013716" />
		</inertial>
		<visual>
			<origin xyz="0 0 0" rpy="0 0 0" />
			<geometry>
				<mesh filename="package://pai_cl_12_240823/meshes/r_ankle_pitch_link.STL" />
			</geometry>
			<material name="">
				<color rgba="0.89804 0.91765 0.92941 1" />
			</material>
		</visual>
		<collision>
			<origin xyz="0 0 0" rpy="0 0 0" />
			<geometry>
				<mesh filename="package://pai_cl_12_240823/meshes/r_ankle_pitch_link.STL" />
			</geometry>
		</collision>
	</link>
	<joint name="r_ankle_pitch_joint" type="revolute">
		<origin xyz="0 0 -0.14" rpy="0 0 0" />
		<parent link="r_calf_link" />
		<child link="r_ankle_pitch_link" />
		<axis xyz="0 1 0" />
		<limit lower="-3.14" upper="3.14" effort="21" velocity="21" />
	</joint>
	<link name="r_ankle_roll_link">
		<inertial>
			<origin xyz="0.01258312 0.00017854 -0.01689078" rpy="0 0 0" />
			<mass value="0.58347191" />
			<inertia ixx="0.00052164" ixy="-1.83E-06" ixz="-0.00017071" iyy="0.00089826" iyz="-1E-08" izz="0.00070959" />
		</inertial>
		<visual>
			<origin xyz="0 0 0" rpy="0 0 0" />
			<geometry>
				<mesh filename="package://pai_cl_12_240823/meshes/r_ankle_roll_link.STL" />
			</geometry>
			<material name="">
				<color rgba="0.89804 0.91765 0.92941 1" />
			</material>
		</visual>
		<collision>
			<origin xyz="0 0 0" rpy="0 0 0" />
			<geometry>
				<mesh filename="package://pai_cl_12_240823/meshes/r_ankle_roll_link.STL" />
			</geometry>
		</collision>
	</link>
	<joint name="r_ankle_roll_joint" type="revolute">
		<origin xyz="0.051 0.0275 0" rpy="0 0 0" />
		<parent link="r_ankle_pitch_link" />
		<child link="r_ankle_roll_link" />
		<axis xyz="1 0 0" />
		<limit lower="-3.14" upper="3.14" effort="21" velocity="21" />
	</joint>
	<link name="l_hip_yaw_link">
		<inertial>
			<origin xyz="0.00173618 0.03062004 -0.00030829" rpy="0 0 0" />
			<mass value="0.34618014" />
			<inertia ixx="0.00017242" ixy="-1.05E-06" ixz="-7.7E-07" iyy="0.00016647" iyz="1.88E-06" izz="0.0001739" />
		</inertial>
		<visual>
			<origin xyz="0 0 0" rpy="0 0 0" />
			<geometry>
				<mesh filename="package://pai_cl_12_240823/meshes/l_hip_yaw_link.STL" />
			</geometry>
			<material name="">
				<color rgba="1 1 1 1" />
			</material>
		</visual>
		<collision>
			<origin xyz="0 0 0" rpy="0 0 0" />
			<geometry>
				<mesh filename="package://pai_cl_12_240823/meshes/l_hip_yaw_link.STL" />
			</geometry>
		</collision>
	</link>
	<joint name="l_hip_yaw_joint" type="revolute">
		<origin xyz="-0.0028186 0.0482 -0.031" rpy="0 0 0" />
		<parent link="base_link" />
		<child link="l_hip_yaw_link" />
		<axis xyz="0 1 0" />
		<limit lower="-3.14" upper="3.14" effort="21" velocity="21" />
	</joint>
	<link name="l_hip_roll_link">
		<inertial>
			<origin xyz="-0.025898 0.00026595 -0.061275" rpy="0 0 0" />
			<mass value="0.3854" />
			<inertia ixx="0.00036232" ixy="1.64E-06" ixz="3.175E-05" iyy="0.00042107" iyz="2.7E-07" izz="0.00022943" />
		</inertial>
		<visual>
			<origin xyz="0 0 0" rpy="0 0 0" />
			<geometry>
				<mesh filename="package://pai_cl_12_240823/meshes/l_hip_roll_link.STL" />
			</geometry>
			<material name="">
				<color rgba="0.79216 0.81961 0.93333 1" />
			</material>
		</visual>
		<collision>
			<origin xyz="0 0 0" rpy="0 0 0" />
			<geometry>
				<mesh filename="package://pai_cl_12_240823/meshes/l_hip_roll_link.STL" />
			</geometry>
		</collision>
	</link>
	<joint name="l_hip_roll_joint" type="revolute">
		<origin xyz="0.0245 0.032 0" rpy="0 0 0" />
		<parent link="l_hip_yaw_link" />
		<child link="l_hip_roll_link" />
		<axis xyz="1 0 0" />
		<limit lower="-3.14" upper="3.14" effort="21" velocity="21" />
	</joint>
	<link name="l_thigh_link">
		<inertial>
			<origin xyz="0 -0.013296 -0.030451" rpy="0 0 0" />
			<mass value="0.074503" />
			<inertia ixx="7.118E-05" ixy="0" ixz="-1.0152E-20" iyy="3.643E-05" iyz="0" izz="5.177E-05" />
		</inertial>
		<visual>
			<origin xyz="0 0 0" rpy="0 0 0" />
			<geometry>
				<mesh filename="package://pai_cl_12_240823/meshes/l_thigh_link.STL" />
			</geometry>
			<material name="">
				<color rgba="0.79216 0.81961 0.93333 1" />
			</material>
		</visual>
		<collision>
			<origin xyz="0 0 0" rpy="0 0 0" />
			<geometry>
				<mesh filename="package://pai_cl_12_240823/meshes/l_thigh_link.STL" />
			</geometry>
		</collision>
	</link>
	<joint name="l_thigh_joint" type="revolute">
		<origin xyz="-0.0245 0 -0.0935" rpy="0 0 0" />
		<parent link="l_hip_roll_link" />
		<child link="l_thigh_link" />
		<axis xyz="0 0 1" />
		<limit lower="-3.14" upper="3.14" effort="21" velocity="21" />
	</joint>
	<link name="l_calf_link">
		<inertial>
			<origin xyz="4.96E-05 -0.02387245 0" rpy="0 0 0" />
			<mass value="0.7182" />
			<inertia ixx="0.00318059" ixy="-7E-08" ixz="8.87E-06" iyy="0.00319842" iyz="-1.671E-05" izz="0.00029771" />
		</inertial>
		<visual>
			<origin xyz="0 0 0" rpy="0 0 0" />
			<geometry>
				<mesh filename="package://pai_cl_12_240823/meshes/l_calf_link.STL" />
			</geometry>
			<material name="">
				<color rgba="0.75294 0.75294 0.75294 1" />
			</material>
		</visual>
		<collision>
			<origin xyz="0 0 0" rpy="0 0 0" />
			<geometry>
				<mesh filename="package://pai_cl_12_240823/meshes/l_calf_link.STL" />
			</geometry>
		</collision>
	</link>
	<joint name="l_calf_joint" type="revolute">
		<origin xyz="0 0.0275 -0.046" rpy="0 0 0" />
		<parent link="l_thigh_link" />
		<child link="l_calf_link" />
		<axis xyz="0 1 0" />
		<limit lower="-3.14" upper="3.14" effort="21" velocity="21" />
	</joint>
	<link name="l_ankle_pitch_link">
		<inertial>
			<origin xyz="0.02577677 -0.02854579 0" rpy="0 0 0" />
			<mass value="0.1322312" />
			<inertia ixx="9.848E-05" ixy="-3.56E-06" ixz="0" iyy="7.022E-05" iyz="0" izz="0.00013716" />
		</inertial>
		<visual>
			<origin xyz="0 0 0" rpy="0 0 0" />
			<geometry>
				<mesh filename="package://pai_cl_12_240823/meshes/l_ankle_pitch_link.STL" />
			</geometry>
			<material name="">
				<color rgba="0.89804 0.91765 0.92941 1" />
			</material>
		</visual>
		<collision>
			<origin xyz="0 0 0" rpy="0 0 0" />
			<geometry>
				<mesh filename="package://pai_cl_12_240823/meshes/l_ankle_pitch_link.STL" />
			</geometry>
		</collision>
	</link>
	<joint name="l_ankle_pitch_joint" type="revolute">
		<origin xyz="0 0 -0.14" rpy="0 0 0" />
		<parent link="l_calf_link" />
		<child link="l_ankle_pitch_link" />
		<axis xyz="0 1 0" />
		<limit lower="-3.14" upper="3.14" effort="21" velocity="21" />
	</joint>
	<link name="l_ankle_roll_link">
		<inertial>
			<origin xyz="0.01258312 0.00017854 -0.01689078" rpy="0 0 0" />
			<mass value="0.58347191" />
			<inertia ixx="0.00052164" ixy="-1.83E-06" ixz="-0.00017071" iyy="0.00089826" iyz="-1E-08" izz="0.00070959" />
		</inertial>
		<visual>
			<origin xyz="0 0 0" rpy="0 0 0" />
			<geometry>
				<mesh filename="package://pai_cl_12_240823/meshes/l_ankle_roll_link.STL" />
			</geometry>
			<material name="">
				<color rgba="0.89804 0.91765 0.92941 1" />
			</material>
		</visual>
		<collision>
			<origin xyz="0 0 0" rpy="0 0 0" />
			<geometry>
				<mesh filename="package://pai_cl_12_240823/meshes/l_ankle_roll_link.STL" />
			</geometry>
		</collision>
	</link>
	<joint name="l_ankle_roll_joint" type="revolute">
		<origin xyz="0.051 -0.0275 0" rpy="0 0 0" />
		<parent link="l_ankle_pitch_link" />
		<child link="l_ankle_roll_link" />
		<axis xyz="1 0 0" />
		<limit lower="-3.14" upper="3.14" effort="21" velocity="21" />
	</joint>
</robot>
