<?xml version="1.0" encoding="utf-8"?>
<!--
This URDF was automatically created by SolidWorks to URDF Exporter! Originally created by Stephen Brawner (brawner@gmail.com)
Commit Version: 1.6.0-4-g7f85cfe  Build Version: 1.6.7995.38578
For more information, please see http://wiki.ros.org/sw_urdf_exporter
-->
<robot name="pai_cl_12_240823">
	<link name="base_link">
		<inertial>
			<origin xyz="0.00080912 -8.753E-05 0.03920549" rpy="0 0 0" />
			<mass value="1.82" />
			<inertia ixx="0.00829787" ixy="-1.181E-05" ixz="-0.00019642" iyy="0.00916809" iyz="1.354E-05" izz="0.00411404" />
		</inertial>
		<visual>
			<origin xyz="0 0 0" rpy="0 0 0" />
			<geometry>
				<mesh filename="package://pai_cl_12_240823/meshes/base_link.STL" />
			</geometry>
			<material name="">
				<color rgba="0.79216 0.81961 0.93333 1" />
			</material>
		</visual>
		<collision>
			<origin xyz="0 0 0" rpy="0 0 0" />
			<geometry>
				<mesh filename="package://pai_cl_12_240823/meshes/base_link.STL" />
			</geometry>
		</collision>
	</link>
	<link name="r_hip_pitch_link">
		<inertial>
			<origin xyz="0.0010765 -0.030923 -0.00028479" rpy="0 0 0" />
			<mass value="0.37475" />
			<inertia ixx="0.00018843" ixy="-7E-07" ixz="-7E-07" iyy="0.00019327" iyz="1.72E-06" izz="0.00020355" />
		</inertial>
		<visual>
			<origin xyz="0 0 0" rpy="0 0 0" />
			<geometry>
				<mesh filename="package://pai_cl_12_240823/meshes/r_hip_pitch_link.STL" />
			</geometry>
			<material name="">
				<color rgba="0.79216 0.81961 0.93333 1" />
			</material>
		</visual>
		<collision>
			<origin xyz="0 0 0" rpy="0 0 0" />
			<geometry>
				<mesh filename="package://pai_cl_12_240823/meshes/r_hip_pitch_link.STL" />
			</geometry>
		</collision>
	</link>
	<joint name="r_hip_pitch_joint" type="revolute">
		<origin xyz="-0.0028186 -0.0482 -0.031" rpy="0 0 0" />
		<parent link="base_link" />
		<child link="r_hip_pitch_link" />
		<axis xyz="0 1 0" />
		<limit lower="-3.14" upper="3.14" effort="21" velocity="21" />
	</joint>
	<link name="r_hip_roll_link">
		<inertial>
			<origin xyz="-0.025798 0.00024695 -0.059965" rpy="0 0 0" />
			<mass value="0.41506" />
			<inertia ixx="0.00037621" ixy="1.65E-06" ixz="3.105E-05" iyy="0.0004423" iyz="4E-07" izz="0.00024588" />
		</inertial>
		<visual>
			<origin xyz="0 0 0" rpy="0 0 0" />
			<geometry>
				<mesh filename="package://pai_cl_12_240823/meshes/r_hip_roll_link.STL" />
			</geometry>
			<material name="">
				<color rgba="0.79216 0.81961 0.93333 1" />
			</material>
		</visual>
		<collision>
			<origin xyz="0 0 0" rpy="0 0 0" />
			<geometry>
				<mesh filename="package://pai_cl_12_240823/meshes/r_hip_roll_link.STL" />
			</geometry>
		</collision>
	</link>
	<joint name="r_hip_roll_joint" type="revolute">
		<origin xyz="0.0245 -0.032 0" rpy="0 0 0" />
		<parent link="r_hip_pitch_link" />
		<child link="r_hip_roll_link" />
		<axis xyz="1 0 0" />
		<limit lower="-3.14" upper="3.14" effort="21" velocity="21" />
	</joint>
	<link name="r_thigh_link">
		<inertial>
			<origin xyz="0 0.00287888 -0.02541557" rpy="0 0 0" />
			<mass value="0.12098061" />
			<inertia ixx="0.00013404" ixy="0" ixz="0" iyy="6.442E-05" iyz="7.23E-06" izz="9.875E-05" />
		</inertial>
		<visual>
			<origin xyz="0 0 0" rpy="0 0 0" />
			<geometry>
				<mesh filename="package://pai_cl_12_240823/meshes/r_thigh_link.STL" />
			</geometry>
			<material name="">
				<color rgba="0.89804 0.91765 0.92941 1" />
			</material>
		</visual>
		<collision>
			<origin xyz="0 0 0" rpy="0 0 0" />
			<geometry>
				<mesh filename="package://pai_cl_12_240823/meshes/r_thigh_link.STL" />
			</geometry>
		</collision>
	</link>
	<joint name="r_thigh_joint" type="revolute">
		<origin xyz="-0.0245 0 -0.0935" rpy="0 0 0" />
		<parent link="r_hip_roll_link" />
		<child link="r_thigh_link" />
		<axis xyz="0 0 1" />
		<limit lower="-3.14" upper="3.14" effort="21" velocity="21" />
	</joint>
	<link name="r_calf_link">
		<!-- <inertial>
			<origin xyz="4.634E-05 0.02433028 -0.06931881" rpy="0 0 0" />
			<mass value="0.7701909" />
			<inertia ixx="0.00330426" ixy="9E-08" ixz="-8.87E-06" iyy="0.00019962" iyz="2.29E-06" izz="0.00032106" />
		</inertial> -->
		<inertial>
			<origin xyz="4.686E-05 0.02435698 -0.06983241" rpy="0 0 0" />
			<mass value="0.7601909" />
			<inertia ixx="0.00325687" ixy="-9E-08" ixz="8.91E-06" iyy="0.00327684" iyz="6.4E-07" izz="0.00031685" />
		</inertial>
		<visual>
			<origin xyz="0 0 0" rpy="0 0 0" />
			<geometry>
				<mesh filename="package://pai_cl_12_240823/meshes/r_calf_link.STL" />
			</geometry>
			<material name="">
				<color rgba="0.79216 0.81961 0.93333 1" />
			</material>
		</visual>
		<collision>
			<origin xyz="0 0 0" rpy="0 0 0" />
			<geometry>
				<mesh filename="package://pai_cl_12_240823/meshes/r_calf_link.STL" />
			</geometry>
		</collision>
	</link>
	<joint name="r_calf_joint" type="revolute">
		<origin xyz="0 -0.0275 -0.046" rpy="0 0 0" />
		<parent link="r_thigh_link" />
		<child link="r_calf_link" />
		<axis xyz="0 1 0" />
		<limit lower="-3.14" upper="3.14" effort="21" velocity="21" />
	</joint>
	<link name="r_ankle_pitch_link">
		<inertial>
			<origin xyz="0.02577677 0.0285458 0" rpy="0 0 0" />
			<mass value="0.1322312" />
			<inertia ixx="9.848E-05" ixy="3.56E-06" ixz="0" iyy="7.022E-05" iyz="0" izz="0.00013716" />
		</inertial>
		<visual>
			<origin xyz="0 0 0" rpy="0 0 0" />
			<geometry>
				<mesh filename="package://pai_cl_12_240823/meshes/r_ankle_pitch_link.STL" />
			</geometry>
			<material name="">
				<color rgba="0.89804 0.91765 0.92941 1" />
			</material>
		</visual>
		<collision>
			<origin xyz="0 0 0" rpy="0 0 0" />
			<geometry>
				<mesh filename="package://pai_cl_12_240823/meshes/r_ankle_pitch_link.STL" />
			</geometry>
		</collision>
	</link>
	<joint name="r_ankle_pitch_joint" type="revolute">
		<origin xyz="0 0 -0.14" rpy="0 0 0" />
		<parent link="r_calf_link" />
		<child link="r_ankle_pitch_link" />
		<axis xyz="0 1 0" />
		<limit lower="-3.14" upper="3.14" effort="21" velocity="21" />
	</joint>
	<link name="r_ankle_roll_link">
		<inertial>
			<origin xyz="0.012583 0.00017854 -0.016891" rpy="0 0 0" />
			<mass value="0.58347" />
			<inertia ixx="0.00052164" ixy="-1.83E-06" ixz="-0.00017071" iyy="0.00089826" iyz="-1E-08" izz="0.00070959" />
		</inertial>
		<visual>
			<origin xyz="0 0 0" rpy="0 0 0" />
			<geometry>
				<mesh filename="package://pai_cl_12_240823/meshes/r_ankle_roll_link.STL" />
			</geometry>
			<material name="">
				<color rgba="0.79216 0.81961 0.93333 1" />
			</material>
		</visual>
		<collision>
			<origin xyz="0 0 0" rpy="0 0 0" />
			<geometry>
				<mesh filename="package://pai_cl_12_240823/meshes/r_ankle_roll_link.STL" />
			</geometry>
		</collision>
	</link>
	<joint name="r_ankle_roll_joint" type="revolute">
		<origin xyz="0.051 0.0275 0" rpy="0 0 0" />
		<parent link="r_ankle_pitch_link" />
		<child link="r_ankle_roll_link" />
		<axis xyz="1 0 0" />
		<limit lower="-3.14" upper="3.14" effort="21" velocity="21" />
	</joint>
	<link name="l_hip_pitch_link">
		<inertial>
			<origin xyz="0.0010765 0.030923 -0.00028479" rpy="0 0 0" />
			<mass value="0.37475" />
			<inertia ixx="0.00018843" ixy="-7E-07" ixz="-7E-07" iyy="0.00019327" iyz="1.72E-06" izz="0.00020355" />
		</inertial>
		<visual>
			<origin xyz="0 0 0" rpy="0 0 0" />
			<geometry>
				<mesh filename="package://pai_cl_12_240823/meshes/l_hip_pitch_link.STL" />
			</geometry>
			<material name="">
				<color rgba="0.89804 0.91765 0.92941 1" />
			</material>
		</visual>
		<collision>
			<origin xyz="0 0 0" rpy="0 0 0" />
			<geometry>
				<mesh filename="package://pai_cl_12_240823/meshes/l_hip_pitch_link.STL" />
			</geometry>
		</collision>
	</link>
	<joint name="l_hip_pitch_joint" type="revolute">
		<origin xyz="-0.0028186 0.0482 -0.031" rpy="0 0 0" />
		<parent link="base_link" />
		<child link="l_hip_pitch_link" />
		<axis xyz="0 1 0" />
		<limit lower="-3.14" upper="3.14" effort="21" velocity="21" />
	</joint>
	<link name="l_hip_roll_link">
		<inertial>
			<origin xyz="-0.025798 0.00024695 -0.059965" rpy="0 0 0" />
			<mass value="0.41506" />
			<inertia ixx="0.00037621" ixy="1.65E-06" ixz="3.105E-05" iyy="0.0004423" iyz="4E-07" izz="0.00024588" />
		</inertial>
		<visual>
			<origin xyz="0 0 0" rpy="0 0 0" />
			<geometry>
				<mesh filename="package://pai_cl_12_240823/meshes/l_hip_roll_link.STL" />
			</geometry>
			<material name="">
				<color rgba="0.79216 0.81961 0.93333 1" />
			</material>
		</visual>
		<collision>
			<origin xyz="0 0 0" rpy="0 0 0" />
			<geometry>
				<mesh filename="package://pai_cl_12_240823/meshes/l_hip_roll_link.STL" />
			</geometry>
		</collision>
	</link>
	<joint name="l_hip_roll_joint" type="revolute">
		<origin xyz="0.0245 0.032 0" rpy="0 0 0" />
		<parent link="l_hip_pitch_link" />
		<child link="l_hip_roll_link" />
		<axis xyz="1 0 0" />
		<limit lower="-3.14" upper="3.14" effort="21" velocity="21" />
	</joint>
	<link name="l_thigh_link">
		<inertial>
			<origin xyz="0 -0.00286926 -0.02541557" rpy="0 0 0" />
			<mass value="0.12098061" />
			<inertia ixx="0.00013405" ixy="0" ixz="0" iyy="6.442E-05" iyz="-7.26E-06" izz="9.875E-05" />
		</inertial>
		<visual>
			<origin xyz="0 0 0" rpy="0 0 0" />
			<geometry>
				<mesh filename="package://pai_cl_12_240823/meshes/l_thigh_link.STL" />
			</geometry>
			<material name="">
				<color rgba="0.89804 0.91765 0.92941 1" />
			</material>
		</visual>
		<collision>
			<origin xyz="0 0 0" rpy="0 0 0" />
			<geometry>
				<mesh filename="package://pai_cl_12_240823/meshes/l_thigh_link.STL" />
			</geometry>
		</collision>
	</link>
	<joint name="l_thigh_joint" type="revolute">
		<origin xyz="-0.0245 0 -0.0935" rpy="0 0 0" />
		<parent link="l_hip_roll_link" />
		<child link="l_thigh_link" />
		<axis xyz="0 0 1" />
		<limit lower="-3.14" upper="3.14" effort="21" velocity="21" />
	</joint>
	<link name="l_calf_link">
		<inertial>
			<origin xyz="4.686E-05 -0.02435698 -0.06983241" rpy="0 0 0" />
			<mass value="0.7601909" />
			<inertia ixx="0.00325687" ixy="-9E-08" ixz="8.91E-06" iyy="0.00327684" iyz="6.4E-07" izz="0.00031685" />
		</inertial>
		<visual>
			<origin xyz="0 0 0" rpy="0 0 0" />
			<geometry>
				<mesh filename="package://pai_cl_12_240823/meshes/l_calf_link.STL" />
			</geometry>
			<material name="">
				<color rgba="0.75294 0.75294 0.75294 1" />
			</material>
		</visual>
		<collision>
			<origin xyz="0 0 0" rpy="0 0 0" />
			<geometry>
				<mesh filename="package://pai_cl_12_240823/meshes/l_calf_link.STL" />
			</geometry>
		</collision>
	</link>
	<joint name="l_calf_joint" type="revolute">
		<origin xyz="0 0.0275 -0.046" rpy="0 0 0" />
		<parent link="l_thigh_link" />
		<child link="l_calf_link" />
		<axis xyz="0 1 0" />
		<limit lower="-3.14" upper="3.14" effort="21" velocity="21" />
	</joint>
	<link name="l_ankle_pitch_link">
		<inertial>
			<origin xyz="0.02577677 -0.02854579 0" rpy="0 0 0" />
			<mass value="0.1322312" />
			<inertia ixx="9.848E-05" ixy="-3.56E-06" ixz="0" iyy="7.022E-05" iyz="0" izz="0.00013716" />
		</inertial>
		<visual>
			<origin xyz="0 0 0" rpy="0 0 0" />
			<geometry>
				<mesh filename="package://pai_cl_12_240823/meshes/l_ankle_pitch_link.STL" />
			</geometry>
			<material name="">
				<color rgba="0.89804 0.91765 0.92941 1" />
			</material>
		</visual>
		<collision>
			<origin xyz="0 0 0" rpy="0 0 0" />
			<geometry>
				<mesh filename="package://pai_cl_12_240823/meshes/l_ankle_pitch_link.STL" />
			</geometry>
		</collision>
	</link>
	<joint name="l_ankle_pitch_joint" type="revolute">
		<origin xyz="0 0 -0.14" rpy="0 0 0" />
		<parent link="l_calf_link" />
		<child link="l_ankle_pitch_link" />
		<axis xyz="0 1 0" />
		<limit lower="-3.14" upper="3.14" effort="21" velocity="21" />
	</joint>
	<link name="l_ankle_roll_link">
		<inertial>
			<origin xyz="0.012583 0.00017854 -0.016891" rpy="0 0 0" />
			<mass value="0.58347" />
			<inertia ixx="0.00052164" ixy="-1.83E-06" ixz="-0.00017071" iyy="0.00089826" iyz="-1E-08" izz="0.00070959" />
		</inertial>
		<visual>
			<origin xyz="0 0 0" rpy="0 0 0" />
			<geometry>
				<mesh filename="package://pai_cl_12_240823/meshes/l_ankle_roll_link.STL" />
			</geometry>
			<material name="">
				<color rgba="0.89804 0.91765 0.92941 1" />
			</material>
		</visual>
		<collision>
			<origin xyz="0 0 0" rpy="0 0 0" />
			<geometry>
				<mesh filename="package://pai_cl_12_240823/meshes/l_ankle_roll_link.STL" />
			</geometry>
		</collision>
	</link>
	<joint name="l_ankle_roll_joint" type="revolute">
		<origin xyz="0.051 -0.0275 0" rpy="0 0 0" />
		<parent link="l_ankle_pitch_link" />
		<child link="l_ankle_roll_link" />
		<axis xyz="1 0 0" />
		<limit lower="-3.14" upper="3.14" effort="21" velocity="21" />
	</joint>
</robot>
