<mujoco model="pi_12dof_release_v1">
	<compiler angle="radian" meshdir="../meshes/" eulerseq="zyx" />
	<option timestep="0.001" iterations="50" solver="PGS" gravity="0 0 -9.81">
		<flag sensornoise="enable" frictionloss="enable" />
	</option>
	<size njmax="500" nconmax="100" />
	<visual>
		<quality shadowsize="4096" />
		<map znear="0.05" />
	</visual>
	<default>
		<joint limited="true" />
		<motor ctrllimited="true" />
		<geom condim="4" contype="1" conaffinity="15" solref="0.001 2" friction="0.9 0.2 0.2" />
		<equality solref="0.001 2" />
		<default class="visualgeom">
			<geom material="visualgeom" condim="1" contype="0" conaffinity="0" />
		</default>
		<default class="visualgeom2">
			<geom material="visualgeom2" condim="1" contype="0" conaffinity="0" />
		</default>
		<default class="obstacle">
			<geom material="obstacle" condim="3" contype="1" conaffinity="15" />
		</default>
	</default>
	<asset>
		<texture type="skybox" builtin="gradient" rgb1="0.3 0.5 0.7" rgb2="0 0 0" width="512" height="512" />
		<texture name="texplane" type="2d" builtin="checker" rgb1=".2 .3 .4" rgb2=".1 0.15 0.2" width="512" height="512" mark="cross" markrgb=".8 .8 .8" />
		<texture name="texplane2" type="2d" builtin="checker" rgb1="1 0.3137 0.1843" rgb2="0.0 0.30196 0.38039" width="512" height="512" mark="cross" markrgb=".8 .8 .8" />
		<material name="matplane" reflectance="0." texture="texplane" texrepeat="1 1" texuniform="true" />
		<material name="matplane2" reflectance="0.1" texture="texplane2" texrepeat="1 1" texuniform="true" />
		<material name="obstacle" rgba="0.9 0.6 0.2 1" />
		<material name="visualgeom" rgba="0.5 0.9 0.2 1" />
		<material name="visualgeom2" rgba="0.5 0.9 0.2 1" />
		<mesh name="base_link" file="base_link.STL" />
		<mesh name="r_hip_yaw_link" file="r_hip_yaw_link.STL" />
		<mesh name="r_hip_roll_link" file="r_hip_roll_link.STL" />
		<mesh name="r_thigh_link" file="r_thigh_link.STL" />
		<mesh name="r_calf_link" file="r_calf_link.STL" />
		<mesh name="r_ankle_pitch_link" file="r_ankle_pitch_link.STL" />
		<mesh name="r_ankle_roll_link" file="r_ankle_roll_link.STL" />
		<mesh name="l_hip_yaw_link" file="l_hip_yaw_link.STL" />
		<mesh name="l_hip_roll_link" file="l_hip_roll_link.STL" />
		<mesh name="l_thigh_link" file="l_thigh_link.STL" />
		<mesh name="l_calf_link" file="l_calf_link.STL" />
		<mesh name="l_ankle_pitch_link" file="l_ankle_pitch_link.STL" />
		<mesh name="l_ankle_roll_link" file="l_ankle_roll_link.STL" />
		<hfield name="hf0" nrow="200" ncol="200" size="10 5 0.2 .1" />
	</asset>
	<worldbody>
		<light directional="true" diffuse=".4 .4 .4" specular="0.1 0.1 0.1" pos="0 0 5.0" dir="0 0 -1" castshadow="false" />
		<light directional="true" diffuse=".6 .6 .6" specular="0.2 0.2 0.2" pos="0 0 4" dir="0 0 -1" />
		<geom name="ground" type="plane" size="0 0 1" pos="0.001 0 0" quat="1 0 0 0" material="matplane" condim="1" conaffinity="15" />
		<body name="base_link" pos="0.0 0.0 0.398">
			<inertial pos="0.00242324 -5.699e-05 0.0403008" quat="0.695312 0.00968645 0.00943283 0.718581" mass="2.1609" diaginertia="0.00978249 0.00901239 0.00416199" />
			<joint type="slide" axis="1 0 0" limited="false" />
			<joint type="slide" axis="0 1 0" limited="false" />
			<joint type="slide" axis="0 0 1" limited="false" />
			<joint type="ball" limited="false" />
			<site name="imu" size="0.01" pos="0.0 0 0.0" />
			<geom type="mesh" contype="0" conaffinity="0" group="1" density="0" rgba="1 1 1 1" mesh="base_link" />
			<geom size="0.05 0.05 0.05" pos="0 0 0.08" type="box" rgba="1 1 1 1" />
			<body name="r_hip_yaw_link" pos="0 -0.075 0">
				<inertial pos="-0.0521311 0.00012202 -0.0527354" quat="0.962015 0.00675115 0.27155 0.0272313" mass="0.349538" diaginertia="0.000264257 0.000252453 0.000132199" />
				<joint name="r_hip_yaw_joint" pos="0 0 0" axis="0 0 1" range="-0.8 0.8" />
				<geom type="mesh" contype="0" conaffinity="0" group="1" density="0" rgba="0.89804 0.91765 0.92941 1" mesh="r_hip_yaw_link" />
				<geom size="0.015 0.015 0.015" type="box" rgba="0.89804 0.91765 0.92941 1" />
				<body name="r_hip_roll_link" pos="0 0 -0.059">
					<inertial pos="-0.00214086 0.00022682 -0.00016674" quat="0.502796 0.505088 -0.497459 0.494588" mass="0.674308" diaginertia="0.00101635 0.000989684 0.000316451" />
					<joint name="r_hip_roll_joint" pos="0 0 0" axis="1 0 0" range="-0.5 0.157" />
					<geom type="mesh" contype="0" conaffinity="0" group="1" density="0" rgba="0.89804 0.91765 0.92941 1" mesh="r_hip_roll_link" />
					<geom size="0.015 0.015 0.015" pos="-0.05 0 0" type="box" rgba="0.89804 0.91765 0.92941 1" />
					<body name="r_thigh_link" quat="0.984727 0 -0.174108 0">
						<inertial pos="0.00297238 -0.00090907 -0.080464" quat="0.501385 0.012222 -0.00689819 0.86511" mass="0.11783" diaginertia="0.000339454 0.000338484 2.51724e-05" />
						<joint name="r_thigh_joint" pos="0 0 0" axis="0 1 0" range="-1.2 0.6" />
						<geom type="mesh" contype="0" conaffinity="0" group="1" density="0" rgba="0.89804 0.91765 0.92941 1" mesh="r_thigh_link" />
						<geom size="0.015 0.015 0.05" pos="0 0 -0.07" type="box" rgba="0.89804 0.91765 0.92941 1" />
						<body name="r_calf_link" pos="0 0 -0.15" quat="0.939373 0 0.342898 0">
							<inertial pos="0.00199394 0 -0.0868848" quat="0.694774 0.0379399 -0.0267529 0.717728" mass="0.53091" diaginertia="0.000727466 0.000701949 0.000184555" />
							<joint name="r_calf_joint" pos="0 0 0" axis="0 1 0" range="-0.7 1.6" />
							<geom type="mesh" contype="0" conaffinity="0" group="1" density="0" rgba="0.89804 0.91765 0.92941 1" mesh="r_calf_link" />
							<geom size="0.02 0.02 0.05" pos="0 0 -0.08" type="box" rgba="0.89804 0.91765 0.92941 1" />
							<body name="r_ankle_pitch_link" pos="0 0 -0.17545" quat="0.984727 0 -0.174108 0">
								<inertial pos="0 0 0" quat="0 0.707107 0 0.707107" mass="0.0115844" diaginertia="1.21e-06 1.12e-06 4.5e-07" />
								<joint name="r_ankle_pitch_joint" pos="0 0 0" axis="0 1 0" range="-0.3 0.85" />
								<geom type="mesh" contype="0" conaffinity="0" group="1" density="0" rgba="0.65098 0.61961 0.58824 1" mesh="r_ankle_pitch_link" />
								<geom type="mesh" rgba="0.65098 0.61961 0.58824 1" mesh="r_ankle_pitch_link" />
								<body name="r_ankle_roll_link">
									<inertial pos="0.016631 -2.06e-06 -0.021104" quat="8.74606e-05 0.728576 0.000120919 0.684965" mass="0.26606" diaginertia="0.000460774 0.00039542 0.000101916" />
									<joint name="r_ankle_roll_joint" pos="0 0 0" axis="1 0 0" range="-0.25 0.7" />
									<geom type="mesh" contype="0" conaffinity="0" group="1" density="0" rgba="0.89804 0.91765 0.92941 1" mesh="r_ankle_roll_link" />
									<geom type="mesh" rgba="0.89804 0.91765 0.92941 1" mesh="r_ankle_roll_link" />
								</body>
							</body>
						</body>
					</body>
				</body>
			</body>
			<body name="l_hip_yaw_link" pos="0 0.075 0">
				<inertial pos="-0.0528778 -6.958e-05 -0.0528816" quat="0.964808 -0.00229227 0.262686 -0.011681" mass="0.349538" diaginertia="0.00026833 0.00025056 0.000131309" />
				<joint name="l_hip_yaw_joint" pos="0 0 0" axis="0 0 1" range="-0.8 0.8" />
				<geom type="mesh" contype="0" conaffinity="0" group="1" density="0" rgba="0.89804 0.91765 0.92941 1" mesh="l_hip_yaw_link" />
				<geom size="0.015 0.015 0.015" type="box" rgba="0.89804 0.91765 0.92941 1" />
				<body name="l_hip_roll_link" pos="0 0 -0.059">
					<inertial pos="-0.00198932 -0.00022682 -0.00016674" quat="0.504524 0.503309 -0.495176 0.496928" mass="0.674308" diaginertia="0.00104453 0.00101902 0.000325583" />
					<joint name="l_hip_roll_joint" pos="0 0 0" axis="1 0 0" range="-0.157 0.5" />
					<geom type="mesh" contype="0" conaffinity="0" group="1" density="0" rgba="1 1 1 1" mesh="l_hip_roll_link" />
					<geom size="0.015 0.015 0.015" pos="-0.05 0 0" type="box" rgba="1 1 1 1" />
					<body name="l_thigh_link" quat="0.984727 0 -0.174108 0">
						<inertial pos="0.00290507 0.00062807 -0.0786419" quat="0.83078 -0.00297303 0.00895681 0.55652" mass="0.12056" diaginertia="0.000357584 0.000356824 2.6282e-05" />
						<joint name="l_thigh_joint" pos="0 0 0" axis="0 1 0" range="-1.2 0.6" />
						<geom type="mesh" contype="0" conaffinity="0" group="1" density="0" rgba="0.89804 0.91765 0.92941 1" mesh="l_thigh_link" />
						<geom size="0.015 0.015 0.05" pos="0 0 -0.07" type="box" rgba="0.89804 0.91765 0.92941 1" />
						<body name="l_calf_link" pos="0 0 -0.15" quat="0.939373 0 0.342898 0">
							<inertial pos="0.00199394 0 -0.0868848" quat="0.717484 -0.022377 0.0339637 0.695387" mass="0.53091" diaginertia="0.000689511 0.000666148 0.000149971" />
							<joint name="l_calf_joint" pos="0 0 0" axis="0 1 0" range="-0.7 1.6" />
							<geom type="mesh" contype="0" conaffinity="0" group="1" density="0" rgba="0.89804 0.91765 0.92941 1" mesh="l_calf_link" />
							<geom size="0.02 0.02 0.05" pos="0 0 -0.08" type="box" rgba="0.89804 0.91765 0.92941 1" />
							<body name="l_ankle_pitch_link" pos="0 0 -0.17545" quat="0.984727 0 -0.174108 0">
								<inertial pos="0 0 0" quat="0 0.707107 0 0.707107" mass="0.0115844" diaginertia="1.21e-06 1.12e-06 4.5e-07" />
								<joint name="l_ankle_pitch_joint" pos="0 0 0" axis="0 1 0" range="-0.3 0.85" />
								<geom type="mesh" contype="0" conaffinity="0" group="1" density="0" rgba="0.89804 0.91765 0.92941 1" mesh="l_ankle_pitch_link" />
								<geom type="mesh" rgba="0.89804 0.91765 0.92941 1" mesh="l_ankle_pitch_link" />
								<body name="l_ankle_roll_link">
									<inertial pos="0.016631 -2.06e-06 -0.021104" quat="-0.000101875 0.726707 -0.000110593 0.686947" mass="0.26319" diaginertia="0.000457156 0.00039075 0.000100764" />
									<joint name="l_ankle_roll_joint" pos="0 0 0" axis="1 0 0" range="-0.7 0.25" />
									<geom type="mesh" contype="0" conaffinity="0" group="1" density="0" rgba="0.89804 0.91765 0.92941 1" mesh="l_ankle_roll_link" />
									<geom type="mesh" rgba="0.89804 0.91765 0.92941 1" mesh="l_ankle_roll_link" />
								</body>
							</body>
						</body>
					</body>
				</body>
			</body>
		</body>
	</worldbody>
	<actuator>
		<motor name="r_hip_yaw_joint" joint="r_hip_yaw_joint" gear="1" ctrllimited="true" ctrlrange="-200 200" />
		<motor name="r_hip_roll_joint" joint="r_hip_roll_joint" gear="1" ctrllimited="true" ctrlrange="-200 200" />
		<motor name="r_thigh_joint" joint="r_thigh_joint" gear="1" ctrllimited="true" ctrlrange="-200 200" />
		<motor name="r_calf_joint" joint="r_calf_joint" gear="1" ctrllimited="true" ctrlrange="-200 200" />
		<motor name="r_ankle_pitch_joint" joint="r_ankle_pitch_joint" gear="1" ctrllimited="true" ctrlrange="-200 200" />
		<motor name="r_ankle_roll_joint" joint="r_ankle_roll_joint" gear="1" ctrllimited="true" ctrlrange="-200 200" />
		<motor name="l_hip_yaw_joint" joint="l_hip_yaw_joint" gear="1" ctrllimited="true" ctrlrange="-200 200" />
		<motor name="l_hip_roll_joint" joint="l_hip_roll_joint" gear="1" ctrllimited="true" ctrlrange="-200 200" />
		<motor name="l_thigh_joint" joint="l_thigh_joint" gear="1" ctrllimited="true" ctrlrange="-200 200" />
		<motor name="l_calf_joint" joint="l_calf_joint" gear="1" ctrllimited="true" ctrlrange="-200 200" />
		<motor name="l_ankle_pitch_joint" joint="l_ankle_pitch_joint" gear="1" ctrllimited="true" ctrlrange="-200 200" />
		<motor name="l_ankle_roll_joint" joint="l_ankle_roll_joint" gear="1" ctrllimited="true" ctrlrange="-200 200" />
	</actuator>
	<sensor>
		<!-- Position sensors -->
		<actuatorpos name="r_hip_yaw_joint_p" actuator="r_hip_yaw_joint" user="13" />
		<actuatorpos name="r_hip_roll_joint_p" actuator="r_hip_roll_joint" user="13" />
		<actuatorpos name="r_thigh_joint_p" actuator="r_thigh_joint" user="13" />
		<actuatorpos name="r_calf_joint_p" actuator="r_calf_joint" user="13" />
		<actuatorpos name="r_ankle_pitch_joint_p" actuator="r_ankle_pitch_joint" user="13" />
		<actuatorpos name="r_ankle_roll_joint_p" actuator="r_ankle_roll_joint" user="13" />
		<actuatorpos name="l_hip_yaw_joint_p" actuator="l_hip_yaw_joint" user="13" />
		<actuatorpos name="l_hip_roll_joint_p" actuator="l_hip_roll_joint" user="13" />
		<actuatorpos name="l_thigh_joint_p" actuator="l_thigh_joint" user="13" />
		<actuatorpos name="l_calf_joint_p" actuator="l_calf_joint" user="13" />
		<actuatorpos name="l_ankle_pitch_joint_p" actuator="l_ankle_pitch_joint" user="13" />
		<actuatorpos name="l_ankle_roll_joint_p" actuator="l_ankle_roll_joint" user="13" />
		<!-- Velocity sensors -->
		<actuatorvel name="r_hip_yaw_joint_v" actuator="r_hip_yaw_joint" user="13" noise="1e-3" />
		<actuatorvel name="r_hip_roll_joint_v" actuator="r_hip_roll_joint" user="13" noise="1e-3" />
		<actuatorvel name="r_thigh_joint_v" actuator="r_thigh_joint" user="13" noise="1e-3" />
		<actuatorvel name="r_calf_joint_v" actuator="r_calf_joint" user="13" noise="1e-3" />
		<actuatorvel name="r_ankle_pitch_joint_v" actuator="r_ankle_pitch_joint" user="13" noise="1e-3" />
		<actuatorvel name="r_ankle_roll_joint_v" actuator="r_ankle_roll_joint" user="13" noise="1e-3" />
		<actuatorvel name="l_hip_yaw_joint_v" actuator="l_hip_yaw_joint" user="13" noise="1e-3" />
		<actuatorvel name="l_hip_roll_joint_v" actuator="l_hip_roll_joint" user="13" noise="1e-3" />
		<actuatorvel name="l_thigh_joint_v" actuator="l_thigh_joint" user="13" noise="1e-3" />
		<actuatorvel name="l_calf_joint_v" actuator="l_calf_joint" user="13" noise="1e-3" />
		<actuatorvel name="l_ankle_pitch_joint_v" actuator="l_ankle_pitch_joint" user="13" noise="1e-3" />
		<actuatorvel name="l_ankle_roll_joint_v" actuator="l_ankle_roll_joint" user="13" noise="1e-3" />
		<!-- Force sensors -->
		<actuatorfrc name="r_hip_yaw_joint_f" actuator="r_hip_yaw_joint" user="13" noise="1e-3" />
		<actuatorfrc name="r_hip_roll_joint_f" actuator="r_hip_roll_joint" user="13" noise="1e-3" />
		<actuatorfrc name="r_thigh_joint_f" actuator="r_thigh_joint" user="13" noise="1e-3" />
		<actuatorfrc name="r_calf_joint_f" actuator="r_calf_joint" user="13" noise="1e-3" />
		<actuatorfrc name="r_ankle_pitch_joint_f" actuator="r_ankle_pitch_joint" user="13" noise="1e-3" />
		<actuatorfrc name="r_ankle_roll_joint_f" actuator="r_ankle_roll_joint" user="13" noise="1e-3" />
		<actuatorfrc name="l_hip_yaw_joint_f" actuator="l_hip_yaw_joint" user="13" noise="1e-3" />
		<actuatorfrc name="l_hip_roll_joint_f" actuator="l_hip_roll_joint" user="13" noise="1e-3" />
		<actuatorfrc name="l_thigh_joint_f" actuator="l_thigh_joint" user="13" noise="1e-3" />
		<actuatorfrc name="l_calf_joint_f" actuator="l_calf_joint" user="13" noise="1e-3" />
		<actuatorfrc name="l_ankle_pitch_joint_f" actuator="l_ankle_pitch_joint" user="13" noise="1e-3" />
		<actuatorfrc name="l_ankle_roll_joint_f" actuator="l_ankle_roll_joint" user="13" noise="1e-3" />
		<framequat name="orientation" objtype="site" noise="0.001" objname="imu" />
		<framepos name="position" objtype="site" noise="0.001" objname="imu" />
		<gyro name="angular-velocity" site="imu" noise="0.005" cutoff="34.9" />
		<velocimeter name="linear-velocity" site="imu" noise="0.001" cutoff="30" />
		<accelerometer name="linear-acceleration" site="imu" noise="0.005" cutoff="157" />
		<magnetometer name="magnetometer" site="imu" />
	</sensor>
</mujoco>
